<?xml version="1.0"?>
<robot xmlns:xacro="http://ros.org/wiki/xacro">

    <!-- Definição das variáveis reutilizáveis -->
    <xacro:property name="pi" value="3.141592653589793"/>
    <xacro:property name="wheel_radius" value="0.1"/>
    <xacro:property name="wheel_length" value="0.05"/>

    <!-- Macro para definir uma roda -->
    <xacro:macro name="wheel" params="name x y z joint_name">
        <link name="${name}">
            <visual>
                <geometry>
                    <cylinder radius="${wheel_radius}" length="${wheel_length}"/> <!-- Aumento do tamanho da roda -->
                </geometry>
                <material name="black"/>
            </visual>
            <collision>
                <geometry>
                    <cylinder radius="${wheel_radius}" length="${wheel_length}"/> <!-- Aumento do tamanho da roda -->
                </geometry>
            </collision>
            <inertial>
                <mass value="0.5"/> <!-- Ajuste no valor de massa para refletir o tamanho maior -->
                <inertia ixx="${(1/12) * 0.5 * (3*wheel_radius*wheel_radius + wheel_length*wheel_length)}" ixy="0.0" ixz="0.0"
                    iyy="${(1/12) * 0.5 * (3*wheel_radius*wheel_radius + wheel_length*wheel_length)}" iyz="0.0"
                    izz="${(1/2) * 0.5 * (wheel_radius*wheel_radius)}"/>
            </inertial>
        </link>

        <!-- Defina um joint único passando o nome do joint -->
        <joint name="${joint_name}" type="continuous">
            <parent link="base_link"/>
            <child link="${name}"/>
            <origin xyz="${x} ${y} ${z}" rpy="${-pi/2} 0 0"/>  <!-- RPY = 0,0,0 para alinhamento correto -->
            <axis xyz="0 0 1"/> <!-- Eixo de rotação ao longo do eixo z -->
        </joint>
    </xacro:macro>

</robot>
